Workbook

Sheet 급여대장
A2: 정민호 | B2: =$B$34 -> 1월 | C2: 계약건: | D2: =COUNTIF($C4:$C28,"계약")+(COUNTIF($C4:$C28,"계약2")*2) -> 0 | E2: =COUNTIF(C4:C28,"낙찰수수료") -> 0 | F2: 본사 : 14명 | H2: 0.5 | I2: 0.033
A3: 날짜 | B3: 고객명 | C3: 항목 | D3: VAT | E3: 입금액 | F3: 매출 | G3: 부가세 | H3: 소득신고 | I3: 소득세 | J3: 공제 | K3: 실지급(법인) | L3: 실지급(개인) | M3: 비고
F4: =IF(D4="no",E4,E4/1.1) -> 0 | G4: =IF(D4="no",0,F4*0.1) -> 0 | H4: =IF(D4="no",0,F4*H2) -> 0 | I4: =IF(D4="no",0,H4*3.3%) -> 0 | K4: =IF(D4="no",0,H4-I4-J4) -> 0 | L4: =IF(D4="no",F4*H2-J4,0) -> 0
F5: =IF(D5="no",E5,E5/1.1) -> 0 | G5: =IF(D5="no",0,F5*0.1) -> 0 | H5: =IF(D5="no",0,F5*H2) -> 0 | I5: =IF(D5="no",0,H5*3.3%) -> 0 | K5: =IF(D5="no",0,H5-I5-J5) -> 0 | L5: =IF(D5="no",F5*H2-J5,0) -> 0
F6: =IF(D6="no",E6,E6/1.1) -> 0 | G6: =IF(D6="no",0,F6*0.1) -> 0 | H6: =IF(D6="no",0,F6*H2) -> 0 | I6: =IF(D6="no",0,H6*3.3%) -> 0 | K6: =IF(D6="no",0,H6-I6-J6) -> 0 | L6: =IF(D6="no",F6*H2-J6,0) -> 0 | M6: 수임비용 | Q6: 55만 | R6: 계약1
F7: =IF(D7="no",E7,E7/1.1) -> 0 | G7: =IF(D7="no",0,F7*0.1) -> 0 | H7: =IF(D7="no",0,F7*H2) -> 0 | I7: =IF(D7="no",0,H7*3.3%) -> 0 | K7: =IF(D7="no",0,H7-I7-J7) -> 0 | L7: =IF(D7="no",F7*H2-J7,0) -> 0 | M7: 원() | Q7: 110만 | R7: 계약1
F8: =IF(D8="no",E8,E8/1.1) -> 0 | G8: =IF(D8="no",0,F8*0.1) -> 0 | H8: =IF(D8="no",0,F8*H2) -> 0 | I8: =IF(D8="no",0,H8*3.3%) -> 0 | K8: =IF(D8="no",0,H8-I8-J8) -> 0 | L8: =IF(D8="no",F8*H2-J8,0) -> 0 | M8: 등기, 명도비용 | Q8: 220만 | R8: 계약2
F9: =IF(D9="no",E9,E9/1.1) -> 0 | G9: =IF(D9="no",0,F9*0.1) -> 0 | H9: =IF(D9="no",0,F9*H2) -> 0 | I9: =IF(D9="no",0,H9*3.3%) -> 0 | K9: =IF(D9="no",0,H9-I9-J9) -> 0 | L9: =IF(D9="no",F9*H2-J9,0) -> 0 | M9: 원() | Q9: 1200만원 이상시 팀장수당지급
M10: 원() | P10: =SUM(P5:P9) -> 0
F11: =IF(D11="no",E11,E11/1.1) -> 0 | G11: =IF(D11="no",0,F11*0.1) -> 0 | H11: =IF(D11="no",0,F11*H2) -> 0 | I11: =IF(D11="no",0,H11*3.3%) -> 0 | K11: =IF(D11="no",0,H11-I11-J11) -> 0
F13: =IF(D13="no",E13,E13/1.1) -> 0 | G13: =IF(D13="no",0,F13*0.1) -> 0 | H13: =IF(D13="no",0,F13*H2) -> 0 | I13: =IF(D13="no",0,H13*3.3%) -> 0 | K13: =IF(D13="no",0,H13-I13-J13) -> 0
F14: =IF(D14="no",E14,E14/1.1) -> 0 | G14: =IF(D14="no",0,F14*0.1) -> 0 | H14: =IF(D14="no",0,F14*H2) -> 0 | I14: =IF(D14="no",0,H14*3.3%) -> 0 | K14: =IF(D14="no",0,H14-I14-J14) -> 0 | M14: 총합계 : 원
F15: =IF(D15="no",E15,E15/1.1) -> 0 | G15: =IF(D15="no",0,F15*0.1) -> 0 | H15: =IF(D15="no",0,F15*H2) -> 0 | I15: =IF(D15="no",0,H15*3.3%) -> 0 | K15: =IF(D15="no",0,H15-I15-J15) -> 0
F16: =IF(D16="no",E16,E16/1.1) -> 0 | G16: =IF(D16="no",0,F16*0.1) -> 0 | H16: =IF(D16="no",0,F16*H2) -> 0 | I16: =IF(D16="no",0,H16*3.3%) -> 0 | K16: =IF(D16="no",0,H16-I16-J16) -> 0 | M16: 율해급여
F17: =IF(D17="no",E17,E17/1.1) -> 0 | G17: =IF(D17="no",0,F17*0.1) -> 0 | H17: =IF(D17="no",0,F17*H2) -> 0 | I17: =IF(D17="no",0,H17*3.3%) -> 0 | K17: =IF(D17="no",0,H17-I17-J17) -> 0 | M17: 원
F18: =IF(D18="no",E18,E18/1.1) -> 0 | G18: =IF(D18="no",0,F18*0.1) -> 0 | H18: =IF(D18="no",0,F18*H2) -> 0 | I18: =IF(D18="no",0,H18*3.3%) -> 0 | K18: =IF(D18="no",0,H18-I18-J18) -> 0 | M18: 총합계 : +원
I21: =IF(D21="no",0,H21*3.3%) -> 0 | K21: =IF(D21="no",0,H21-I21-J21) -> 0 | M21: 미지급금액
I22: =IF(D22="no",0,H22*3.3%) -> 0 | K22: =IF(D22="no",0,H22-I22-J22) -> 0 | L22: =IF(D22="no",F22*H9-J22,0) -> 0 | M22: 2,092,516원(2024-08) | P22: 2092516
F23: =IF(D23="no",E23,E23/1.1) -> 0 | G23: =IF(D23="no",0,F23*0.1) -> 0 | H23: =IF(D23="no",0,F23*H2) -> 0 | I23: =IF(D23="no",0,H23*3.3%) -> 0 | K23: =IF(D23="no",0,H23-I23-J23) -> 0 | M23: 2,842,287원(2024-07) | P23: 2842287
A24: 2026-01-00 | B24: 율해급여공제 | F24: =IF(D24="no",E24,E24/1.1) -> 0 | G24: =IF(D24="no",0,F24*0.1) -> 0 | I24: =IF(D24="no",0,H24*3.3%) -> 0 | K24: =IF(D24="no",0,H24-I24-J24) -> 0 | L24: =IF(D24="no",F24*H5-J24,0) -> 0 | M24: 2,110,836원(2024-06) | P24: 2110836
A25: 2026-01-00 | B25: 명도비정산 | F25: =IF(D25="no",E25,E25/1.1) -> 0 | G25: =IF(D25="no",0,F25*0.1) -> 0 | H25: =(E30+E31+N30)/0.967 -> 0 | I25: =IF(D25="no",0,H25*3.3%) -> 0 | K25: =IF(D25="no",0,H25-I25-J25) -> 0 | L25: =IF(D25="no",F25*H8-J25,0) -> 0 | M25: 2,054,302원(2024-05) | P25: 2054302
A26: 2026-01-00 | B26: 개인포상 | F26: =IF(D26="no",E26,E26/1.1) -> 0 | G26: =IF(D26="no",0,F26*0.1) -> 0 | H26: 0 | I26: =IF(D26="no",0,H26*3.3%) -> 0 | K26: =IF(D26="no",0,H26-I26-J26) -> 0 | L26: =IF(D26="no",F26*H9-J26,0) -> 0 | M26: 814,269원(2024-04) | P26: 814269
A27: 2026-01-00 | B27: 직급수당 | I27: =IF(D27="no",0,H27*3.3%) -> 0 | K27: =IF(D27="no",0,H27-I27-J27) -> 0 | L27: =IF(D27="no",F27*H11-J27,0) -> 0 | M27: 미지급총합계
A28: 2026-01-00 | B28: 목표매출포상 | F28: =IF(D28="no",E28,E28/1.1) -> 0 | G28: =IF(D28="no",0,F28*0.1) -> 0 | I28: =IF(D28="no",0,H28*3.3%) -> 0 | L28: 0 | M28: 9,914,210원 | P28: =SUM(P22:P26) -> 9914210
A29: 실적 합계 | E29: =SUM(E4:E28) -> 0 | F29: =SUM(F4:F28) -> 0 | G29: =SUM(G4:G28) -> 0 | H29: =SUM(H4:H28) -> 0 | I29: =SUM(I4:I28) -> 0 | J29: =SUM(J4:J28) -> 0 | K29: =SUM(K4:K28) -> 0 | L29: =SUM(L4:L28) -> 0
A30: 개인포상 | B30: 개인 계약실적 | C30: =D2 -> 0 | D30: 건 | F30: 본사 계약(건) | G30: =C108+C136+C163+C369+C399+C213+C337+C236+C260+C284+C302+C418+C441 -> 46 | I30: 식비공제(법인)
A31: 자동계산 | B31: 개인 매출실적 | C31: =ROUND(F29/10000,0) -> 0 | D31: 만원 | F31: 본사 실적(만원) | G31: =C109+C137+C164+C214+C237+C261+C338+C370+C400+C285+C303+C419+C442 -> 8932
A32: 실적포상, 공제 반영한 최종 정산 | F32: 식비공제후 (법인) 신고액 | H32: =H29-J30 -> 0 | I32: =H32*3.3% -> 0 | J32: =SUM(J29) -> 0 | K32: 5428700 | L32: =L29 -> 0 | M32: =K32 -> 5428700
A34: 서정수 | B34: 1월 | C34: 계약건: | D34: =COUNTIF($C36:$C55,"계약")+(COUNTIF($C36:$C55,"계약2")*2) -> 4 | E34: =COUNTIF(C36:C55,"낙찰수수료") -> 0 | H34: 0.5 | I34: 0.033
A35: 날짜 | B35: 고객명 | C35: 항목 | D35: VAT | E35: 입금액 | F35: 매출 | G35: 부가세 | H35: 소득신고 | I35: 소득세 | J35: 공제 | K35: 실지급(법인) | L35: 실지급(개인) | M35: 비고
A36: 46029 | B36: (주)으뜸 | C36: 계약2 | E36: 2200000 | F36: =IF(D36="no",E36,E36/1.1) -> 2000000 | G36: =IF(D36="no",0,F36*0.1) -> 200000 | H36: =IF(D36="no",0,F36*H34) -> 1000000 | I36: =IF(D36="no",0,H36*3.3%) -> 33000 | K36: =IF(D36="no",0,H36-I36-J36) -> 967000 | L36: =IF(D36="no",F36*H34-J36,0) -> 0
A37: 46048 | B37: (주)가온엔피엘대부 | C37: 계약2 | E37: 2200000 | F37: =IF(D37="no",E37,E37/1.1) -> 2000000 | G37: =IF(D37="no",0,F37*0.1) -> 200000 | H37: =IF(D37="no",0,F37*H482) -> 1000000 | I37: =IF(D37="no",0,H37*3.3%) -> 33000 | K37: =IF(D37="no",0,H37-I37-J37) -> 967000 | L37: =IF(D37="no",F37*H34-J37,0) -> 0
F38: =IF(D38="no",E38,E38/1.1) -> 0 | G38: =IF(D38="no",0,F38*0.1) -> 0 | H38: =IF(D38="no",0,F38*H34) -> 0 | I38: =IF(D38="no",0,H38*3.3%) -> 0 | K38: =IF(D38="no",0,H38-I38-J38) -> 0 | L38: =IF(D38="no",F38*H34-J38,0) -> 0
F39: =IF(D39="no",E39,E39/1.1) -> 0 | G39: =IF(D39="no",0,F39*0.1) -> 0 | H39: =IF(D39="no",0,F39*H34) -> 0 | I39: =IF(D39="no",0,H39*3.3%) -> 0 | K39: =IF(D39="no",0,H39-I39-J39) -> 0 | L39: =IF(D39="no",F39*H34-J39,0) -> 0
F40: =IF(D40="no",E40,E40/1.1) -> 0 | G40: =IF(D40="no",0,F40*0.1) -> 0 | H40: =IF(D40="no",0,F40*H34) -> 0 | I40: =IF(D40="no",0,H40*3.3%) -> 0 | K40: =IF(D40="no",0,H40-I40-J40) -> 0 | L40: =IF(D40="no",F40*H33-J40,0) -> 0
F41: =IF(D41="no",E41,E41/1.1) -> 0 | G41: =IF(D41="no",0,F41*0.1) -> 0 | H41: =IF(D41="no",0,F41*H34) -> 0 | I41: =IF(D41="no",0,H41*3.3%) -> 0 | K41: =IF(D41="no",0,H41-I41-J41) -> 0 | L41: =IF(D41="no",F41*H34-J41,0) -> 0 | P41: =SUM(P36:P40) -> 0
F42: =IF(D42="no",E42,E42/1.1) -> 0 | G42: =IF(D42="no",0,F42*0.1) -> 0 | H42: =IF(D42="no",0,F42*H34) -> 0 | I42: =IF(D42="no",0,H42*3.3%) -> 0 | K42: =IF(D42="no",0,H42-I42-J42) -> 0 | L42: =IF(D42="no",F42*H34-J42,0) -> 0
F43: =IF(D43="no",E43,E43/1.1) -> 0 | G43: =IF(D43="no",0,F43*0.1) -> 0 | H43: =IF(D43="no",0,F43*H34) -> 0 | I43: =IF(D43="no",0,H43*3.3%) -> 0 | K43: =IF(D43="no",0,H43-I43-J43) -> 0 | L43: =IF(D43="no",F43*H34-J43,0) -> 0
F44: =IF(D44="no",E44,E44/1.1) -> 0 | G44: =IF(D44="no",0,F44*0.1) -> 0 | H44: =IF(D44="no",0,F44*H34) -> 0 | I44: =IF(D44="no",0,H44*3.3%) -> 0 | K44: =IF(D44="no",0,H44-I44-J44) -> 0 | L44: =IF(D44="no",F44*H35-J44,0) -> 0
F46: =IF(D46="no",E46,E46/1.1) -> 0 | G46: =IF(D46="no",0,F46*0.1) -> 0 | H46: =IF(D46="no",0,F46*H34) -> 0 | I46: =IF(D46="no",0,H46*3.3%) -> 0 | K46: =IF(D46="no",0,H46-I46-J46) -> 0 | L46: =IF(D46="no",F46*H34-J46,0) -> 0
...

Sheet 계약포상계산
B5: 개인포상<계약건수>
B8: =급여대장!C57 -> 4 | C8: 서정수 | E8: =급여대장!C478 -> 3 | F8: 진성헌 | H8: =급여대장!C1063 -> 5 | I8: 진은경 | K8: =급여대장!C1557 -> 3 | L8: 윤현석 | M8: 전지사(계약) | N8: 1위 | O8: =LARGE(CHOOSE({1,2,3,4}, B8:B25,E8:E25,H8:H25,K8:K25), 1) -> 10 | P8: 10건이상없음
B9: =급여대장!C78 -> 0 | C9: 김민서 | E9: =급여대장!C514 -> 3 | F9: 임태율 | H9: =급여대장!C1159 -> 5 | I9: 박비송 | K9: =급여대장!C1581 -> 5 | L9: 우진솔 | N9: 2위 | O9: =LARGE(CHOOSE({1,2,3,4}, B8:B25,E8:E25,H8:H25,K8:K25), 2) -> 8
B10: =급여대장!C108 -> 0 | C10: 이익규 | E10: =급여대장!C541 -> 1 | F10: 안중현 | H10: =급여대장!C1202 -> 3 | I10: 이태욱 | K10: =급여대장!C1619 -> 1 | L10: 강민석 | N10: 3위 | O10: =LARGE(CHOOSE({1,2,3,4}, B8:B25,E8:E25,H8:H25,K8:K25), 3) -> 6
E11: =급여대장!C582 -> 6 | F11: 이규진 | H11: =급여대장!C1247 -> 5 | I11: 박선호 | K11: =급여대장!C1641 -> 2 | L11: 도정운 | N11: 4위 | O11: =LARGE(CHOOSE({1,2,3,4}, B8:B25,E8:E25,H8:H25,K8:K25), 4) -> 6
B12: =급여대장!C136 -> 1 | C12: 박정규 | E12: =급여대장!C633 -> 3 | F12: 문지성 | H12: =급여대장!C1270 -> 0
B13: =급여대장!C163 -> 2 | C13: 백재원 | E13: =급여대장!C671 -> 4 | F13: 최병철 | H13: =급여대장!C1293 -> 1 | I13: 박종연 | M13: 본사(계약) | N13: 1위 | O13: =LARGE((B8:B25), 1) -> 10
E14: =급여대장!C698 -> 1 | F14: 노연숙 | H14: =급여대장!C1414 -> 2 | I14: 윤미진 | N14: 2위 | O14: =LARGE((B8:B25), 2) -> 8
B15: =급여대장!C213 -> 4 | C15: 정민준 | E15: =급여대장!C727 -> 2 | F15: 신은호 | H15: =급여대장!C1437 -> 1 | I15: 김일환 | N15: 3위 | O15: =LARGE((B8:B25), 3) -> 6
B16: =급여대장!C236 -> 0 | C16: 이진영 | E16: =급여대장!C764 -> 1 | F16: 최진웅 | H16: =급여대장!C1461 -> 0 | I16: 이동휘
B17: =급여대장!C260 -> 1 | C17: 지경현 | E17: =급여대장!C828 -> 4 | F17: 박정윤 | H17: =급여대장!C1479 -> 1 | I17: 조성재
B18: =급여대장!C302 -> 4 | C18: 조육형 | E18: =급여대장!C881 -> 4 | F18: 주효상 | H18: =급여대장!C1503 -> 0
B19: =급여대장!C284 -> 5 | C19: 윤태강 | E19: =급여대장!C932 -> 0 | F19: 조차훈 | H19: =급여대장!C1527 -> 0
B20: =급여대장!C337 -> 6 | C20: 최재명 | E20: 0
B21: =급여대장!C369 -> 10 | C21: 신유진 | E21: 0
B22: =급여대장!C399 -> 2 | C22: 박혜연 | E22: 0
B23: =급여대장!C418 -> 3 | C23: 김진우 | E23: 0
B24: =급여대장!C441 -> 8 | C24: 정수환 | E24: 0
B25: 0 | E25: 0
B28: =급여대장!C59 -> 400 | C28: 서정수 | E28: =급여대장!C479 -> 2510 | F28: 진성헌 | H28: =급여대장!C1064 -> 360 | I28: 진은경 | K28: =급여대장!C1558 -> 722 | L28: 윤현석 | M28: 전지사(매출) | N28: 1위 | O28: =LARGE(CHOOSE({1,2,3,4}, B28:B45,E28:E45,H28:H45,K28:K45), 1) -> 3726
B29: =급여대장!C79 -> 0 | C29: 김민서 | E29: =급여대장!C515 -> 564 | F29: 임태율 | H29: =급여대장!C1160 -> 988 | I29: 박비송 | K29: =급여대장!C1582 -> 1103 | L29: 우진솔 | N29: 2위 | O29: =LARGE(CHOOSE({1,2,3,4}, B28:B45,E28:E45,H28:H45,K28:K45), 2) -> 2510
B30: =급여대장!C109 -> 0 | C30: 이익규 | E30: =급여대장!C542 -> 300 | F30: 안중현 | H30: =급여대장!C1203 -> 315 | I30: 이태욱 | K30: =급여대장!C1620 -> 810 | L30: 강민석 | N30: 3위 | O30: =LARGE(CHOOSE({1,2,3,4}, B28:B45,E28:E45,H28:H45,K28:K45), 3) -> 2105
E31: =급여대장!C583 -> 1059 | F31: 이규진 | H31: =급여대장!C1248 -> 1500 | I31: 박선호 | K31: =급여대장!C1642 -> 300 | L31: 도정운 | N31: 4위 | O31: =LARGE(CHOOSE({1,2,3,4}, B28:B45,E28:E45,H28:H45,K28:K45), 4) -> 1680
B32: =급여대장!C137 -> 98 | C32: 박정규 | E32: =급여대장!C634 -> 150 | F32: 문지성 | H32: =급여대장!C1271 -> 0 | I32: 김준경
B33: =급여대장!C164 -> 110 | C33: 백재원 | E33: =급여대장!C672 -> 882 | F33: 최병철 | H33: =급여대장!C1294 -> 53 | I33: 박종연
E34: =급여대장!C699 -> 1680 | F34: 노연숙 | H34: =급여대장!C1415 -> 150 | I34: 윤미진
B35: =급여대장!C214 -> 669 | C35: 정민준 | E35: =급여대장!C728 -> 110 | F35: 신은호 | H35: =급여대장!C1438 -> 50 | I35: 김일환 | M35: 본사(매출) | N35: 1위 | O35: =LARGE((B28:B45), 1) -> 3726
B36: =급여대장!C237 -> 0 | C36: 이진영 | E36: =급여대장!C765 -> 2105 | F36: 최진웅 | H36: =급여대장!C1462 -> 8 | I36: 이동휘 | N36: 2위 | O36: =LARGE((B28:B45), 2) -> 1359
B37: =급여대장!C261 -> 50 | C37: 지경현 | E37: =급여대장!C829 -> 1501 | F37: 박정윤 | H37: =급여대장!C1480 -> 50 | I37: 조성재 | N37: 3위 | O37: =LARGE((B28:B45), 3) -> 1150
B38: =급여대장!C285 -> 725 | C38: 조육형 | E38: =급여대장!C882 -> 1260 | F38: 주효상 | H38: =급여대장!C1504 -> 0 | I38: 김아현 | N38: 4위 | O38: =LARGE((B28:B45), 4) -> 725
B39: =급여대장!C303 -> 220 | C39: 윤태강 | E39: =급여대장!C933 -> 0 | F39: 조차훈 | I39: 이진우
B40: =급여대장!C338 -> 3726 | C40: 최재명
B41: =급여대장!C370 -> 1150 | C41: 신유진 | E41: 0
B42: =급여대장!C400 -> 475 | C42: 박혜연 | E42: 0
B43: =급여대장!C419 -> 350 | C43: 김진우 | E43: 0
B44: =급여대장!C442 -> 1359 | C44: 정수환 | E44: 0
B45: 0 | E45: 0

Sheet 소득신고
A1: ■ ㈜엘앤씨 사업소득신고 | C1: (1월분)
A3: 금액 | B3: 갑근세(3.3%) | C3: 실지급액 | D3: 이름 | E3: 주민번호 | F3: 주소
A4: =급여대장!H60 -> 4000000 | B4: =A4*3.3% -> 132000 | C4: =A4-B4 -> 3868000 | D4: 서정수 | E4: 760503-1173511 | F4: 경기도 양주시 광적면 가래비11길 30, 108동 703호(성우헤스티아 아파트) | G4: (서정수)
A5: =급여대장!H110 -> 0 | B5: =A5*3.3% -> 0 | C5: =A5-B5 -> 0 | D5: 이익규 | E5: 890105-1173313 | F5: 경기도 의정부시 평화로196, 1520호 (호원동, 신일엘리시움아파트) | Q5: `
A6: =급여대장!H138 -> 467600 | B6: =A6*3.3% -> 15430.8 | C6: =A6-B6 -> 452169.2 | D6: 박정규 | E6: 901022-1024715 | F6: 경기도 의정부시 회룡로137번길 30, 101동 405호 (호원동, 현대아파트)
A7: =급여대장!K165/0.967 -> 521000 | B7: =A7*3.3% -> 17193 | C7: =A7-B7 -> 503807 | D7: 백재원 | E7: 910705-1037118 | F7: 서울특별시 서대문구 연희로39라길 12, 101호 (홍은동)
A9: =급여대장!K215/0.967 -> 3284881.8 | B9: =A9*3.3% -> 108401.1 | C9: =A9-B9 -> 3176480.7 | D9: 정민준 | E9: 880224-1030011 | F9: 경기도 양주시 고릉말로46번길 38-8, 광명빌라 B동 302호
A10: =급여대장!K262/0.967 -> 203464.32 | B10: =A10*3.3% -> 6714.3226 | C10: =A10-B10 -> 196750 | D10: 지경현 | E10: 930917-1043211 | F10: 경기도 고양시 일산서구 산현로132번길 10, 다동 202호(일산동, 두성빌라)
A11: =급여대장!H286 -> 3643545.5 | B11: =A11*3.3% -> 120237 | C11: =A11-B11 -> 3523308.5 | D11: 조육형 | E11: 691201-1398625 | F11: 경기도 의정부시 호국로1142번길 22, 108동 402호 (가능동, 브라운스통흥선)
A12: =급여대장!H304 -> 1018300 | B12: =A12*3.3% -> 33603.9 | C12: =A12-B12 -> 984696.1 | D12: 윤태강 | E12: 880319-1057317 | F12: 경기도 고양시 일산동구 강송로196, 107동 1205호 (마두동, 강촌마을)
A14: =급여대장!K339/0.967 -> 16754369 | B14: =A14*3.3% -> 552894.18 | C14: =A14-B14 -> 16201475 | D14: 최재명 | E14: 760404-1537918 | F14: 경기도 남양주시 별내2로 63, 3705동 801호 (별내동, 별내신도시 쌍용예가)
A15: =급여대장!K371/0.967 -> 6304000 | B15: =A15*3.3% -> 208032 | C15: =A15-B15 -> 6095968 | D15: 이동건 | E15: 710215-1809038 | F15: 경기도 포천시 소흘읍 태봉로83 503동 105호(추산마을주공아파트)
A16: =급여대장!H401 -> 2509272.7 | B16: =A16*3.3% -> 82806 | C16: =A16-B16 -> 2426466.7 | D16: 박혜연 | E16: 740721-2173917 | F16: 경기도 의정부시 범골로63번길 31 223동 201호 (의정부동, 롯데캐슬 골드파크 아파트
A17: =급여대장!H420 -> 1744700 | B17: =A17*3.3% -> 57575.1 | C17: =A17-B17 -> 1687124.9 | D17: 김진우 | E17: 760125-1058011 | F17: 경기도 하남시 미사강변한강로410번길 87, 202호 (덕풍동)
A18: =급여대장!H443 -> 6819600 | B18: =A18*3.3% -> 225046.8 | C18: =A18-B18 -> 6594553.2 | D18: 정수환 | E18: 851209-1032917 | F18: 서울특별시 강서구 곰달래로24길 12, 402호(화곡동, 동양하우징)
A20: =급여대장!K480/0.967 -> 15033063 | B20: =A20*3.3% -> 496091.07 | C20: =A20-B20 -> 14536972 | D20: 진성헌 | E20: 750115-1173513 | F20: 경기도 양주시 옥정서로1길 60, 옥정더퍼스트 아파트 1513동 1203호
A22: =급여대장!K516/0.967 -> 4365194.4 | B22: =A22*3.3% -> 144051.42 | C22: =A22-B22 -> 4221143 | D22: 임태율 | E22: 820505-1553427 | F22: 서울특별시 양천구 남부순환로83길 18, 202동 1303호 (신월동, 목동센트럴아이파크위브 2단지) | G22: (임태율)
A23: =급여대장!K584/0.967 -> 5244162.5 | B23: =A23*3.3% -> 173057.36 | C23: =A23-B23 -> 5071105.2 | D23: 이규진 | E23: 830228-2241214 | F23: 서울특별시 서대문구 이화여대8길 62, 101동 1806호 (북아현동, 두산아파트)
A24: =급여대장!H635 -> 703125 | B24: =A24*3.3% -> 23203.125 | C24: =A24-B24 -> 679921.87 | D24: 문지성 | E24: 781024-2233615 | F24: 서울특별시 강남구 밤고개로21길 25, 314동 103호 (자곡동, 래미안포레)
A25: =급여대장!H673 -> 4246934 | B25: =A25*3.3% -> 140148.82 | C25: =A25-B25 -> 4106785.2 | D25: 최병철 | E25: 750412-1233411 | F25: 경기도 고양시 덕양구 백양로 126, 1104동 1306호(화정동, 은빛마을)
A26: =급여대장!H700 -> 8335875 | B26: =A26*3.3% -> 275083.88 | C26: =A26-B26 -> 8060791.1 | D26: 노연숙 | E26: 710124-2546213 | F26: 경기도 고양시 덕양구 은빛로17번길 13
A27: =급여대장!K729/0.967 -> 550000 | B27: =A27*3.3% -> 18150 | C27: =A27-B27 -> 531850 | D27: 신은호 | E27: 831218-1006310 | F27: 서울특별시 구로구 오리로22길 34, 나동 302호 (궁동, 청실빌라)
A29: =급여대장!H766 -> 11607363 | B29: =A29*3.3% -> 383042.98 | C29: =A29-B29 -> 11224320 | D29: 최진웅 | E29: 810617-1064910 | F29: 경기도 고양시 덕양구 지축로 55, 106동 2603호(지축동, 지축역센트럴푸르지오)
A30: =급여대장!K830/0.967 -> 7405464.3 | B30: =A30*3.3% -> 244380.32 | C30: =A30-B30 -> 7161084 | D30: 박정윤 | E30: 800107-2553618 | F30: 인천광역시 연수구 새말로20, 505동 504호(연수동, 성일아파트)
A31: =급여대장!K883/0.967 -> 6266150 | B31: =A31*3.3% -> 206782.95 | C31: =A31-B31 -> 6059367 | D31: 주효상 | E31: 840123-1677317 | F31: 대구광역시 동구 동북로 340, 1008동 902호 (신암동, 동대구해모로스퀘어웨스트)
A32: =급여대장!H934 -> 0 | B32: =A32*3.3% -> 0 | C32: =A32-B32 -> 0 | D32: 김효섭 | E32: 770323-1637025 | F32: 서울특별시 중랑구 중랑천로2길 34-6(면목동) | G32: (조차훈)
A33: 0 | B33: =A33*3.3% -> 0 | C33: =A33-B33 -> 0 | D33: 장익성 | E33: 740925-1566110 | F33: 경기도 성남시 분당구 무지개로 144, 503동 1404호
A35: =급여대장!H1067 -> 1713850 | B35: =A35*3.3% -> 56557.05 | C35: =A35-B35 -> 1657292.9 | D35: 진은경 | E35: 780323-2094929 | F35: 부산광역시 남구 고동골로97번길 67, 702호 (문현동, 광원아파트)
A36: =급여대장!K1161/0.967 -> 4830822.7 | B36: =A36*3.3% -> 159417.15 | C36: =A36-B36 -> 4671405.6 | D36: 박비송 | E36: 870528-2111117 | F36: 부산광역시 수영구 광안해변로 311, 909호(민락동, 서희스타힐스센텀프리모)
A37: =급여대장!K1204/0.967 -> 1530737 | B37: =A37*3.3% -> 50514.323 | C37: =A37-B37 -> 1480222.7 | D37: 이태욱 | E37: 911111-1120616 | F37: 경상남도 양산시 물금읍 동중7길 21, A동 703호(삼위로얄아파트))
A38: =급여대장!K1249/0.967 -> 7500909.1 | B38: =A38*3.3% -> 247530 | C38: =A38-B38 -> 7253379.1 | D38: 박선호 | E38: 821230-1122327 | F38: 부산광역시 금정구 식물원로9번길 15, 101동2605호 (장전삼정그린코아더베스트)
A39: =급여대장!K1295/0.967 -> 277272.73 | B39: =A39*3.3% -> 9150 | C39: =A39-B39 -> 268122.73 | D39: 박종연 | E39: 840808-1559513 | F39: 경남 양산시 물금읍 백호로 156, 우성스마트시티뷰 101동 703호
A40: =급여대장!H1416 -> 712000 | B40: =A40*3.3% -> 23496 | C40: =A40-B40 -> 688504 | D40: 윤미진 | E40: 810926-2094210 | F40: 부산광역시 동래구 금강로 131번길 42, 201동, 902호 (레미안포레스티지)
A41: =급여대장!H1439 -> 250000 | B41: =A41*3.3% -> 8250 | C41: =A41-B41 -> 241750 | D41: 김일환 | E41: 880215-1126712 | F41: 부산광역시 금정구 체육공원로 56, 502호(구서동, 태평아파트)
A42: =급여대장!H1463 -> 72818.182 | B42: =A42*3.3% -> 2403 | C42: =A42-B42 -> 70415.182 | D42: 이동휘 | E42: 870424-1841912 | F42: 부산광역시 북구 상학로 35, 102동 1105호(만덕동, 더 래디언트 금정산_
A43: =급여대장!H1481 -> 200000 | B43: =A43*3.3% -> 6600 | C43: =A43-B43 -> 193400 | D43: 조성재 | E43: 930324-1094711 | F43: 부산광역시 부산진구 전포대로306번길 16,1102호(전포동, 르씨엘파크)
A45: =급여대장!H1559 -> 4681479.7 | B45: =A45*3.3% -> 154488.83 | C45: =A45-B45 -> 4526990.9 | D45: 윤현석 | E45: 841219-1063729 | F45: 대전광역시 중구 태평로 15, 122동 701호(태평동, 버드내마을아파트)
A46: =급여대장!K1583/0.967 -> 5417134.6 | B46: =A46*3.3% -> 178765.44 | C46: =A46-B46 -> 5238369.2 | D46: 우진솔 | E46: 941215-2078618 | F46: 대전광역시 서구 탄방로 50-21, 502호(탄방동, 드림빌라)
A47: =급여대장!H1621 -> 3849950 | B47: =A47*3.3% -> 127048.35 | C47: =A47-B47 -> 3722901.6 | D47: 강민석 | E47: 981208-1216119 | F47: 대전시 서구 괴정동 74-10, 304호
A48: =급여대장!H1643 -> 1289650 | B48: =A48*3.3% -> 42558.45 | C48: =A48-B48 -> 1247091.5 | D48: 도정운 | E48: 910228-2735912 | F48: 대전광역시 중구 보문산로161번길 55, 101동 508호 (문화동, 주공아파트)
...
